Workbook

Sheet GESTAO CREDITO E PAGAMENTOS
A1: GESTÃO DE CRÉDITO E PAGAMENTOS 2025 - 2026 | F1: =NOW() -> 46296.634
J2: comparative
A3: INVOICE (EXPORT.) | B3: CUSTOMER | C3: PAIS | D3: ORDER NBR | E3: DATA PROFORM-INVOICE | F3: DATA COLETA (ESTIMADA) | G3: PAYMENT TERMS | H3: days | I3: DATA VENCIMENTO/ DEADLINE | J3: PROFORMA (2026) | K3: DIF PROFORM VS INVOICE FINAL 2026) | L3: TOTAL DUE PAYMENT-AS PER FINAL INVOICE US$ | M3: ADVANCE PAYMENT / FINAL PAYM'T/ NC (US$) | N3: TOTAL DUE BALANCE (US$) | O3: VALOR TOTAL R$ | P3: NÚMERO NF | Q3: STATUS PGTO | R3: OBSERV. | S3: SALES COM. PAID?
A4: 135.24 | B4: DIVINO | D4: 5889 | E4: 45660 | F4: 45660 | G4: 50% Pre Payment - 50% After Received | H4: 30 | I4: =Tabela1[[#This Row],[DATA COLETA (ESTIMADA)]]+Tabela1[[#This Row],[days]] -> 45690 | L4: 22814.54 | M4: 22814.54 | N4: =Tabela1[[#This Row],[ADVANCE PAYMENT / FINAL PAYM''T/ NC (US$)]]-Tabela1[[#This Row],[TOTAL DUE PAYMENT-AS PER FINAL INVOICE US$]] -> 0 | O4: =10017.52+ 74431.82 -> 84449.34 | P4: 56.541 / 56.509 | Q4: paga | R4: PV5321 - NF 56.528 clxd
A5: 136.25 | B5: DIVINO | D5: 5889 | E5: 45679 | F5: 45679 | G5: 50% Pre Payment - 50% After Received | H5: 30 | I5: =Tabela1[[#This Row],[DATA COLETA (ESTIMADA)]]+Tabela1[[#This Row],[days]] -> 45709 | L5: 1623.42 | M5: 1623.42 | N5: =Tabela1[[#This Row],[ADVANCE PAYMENT / FINAL PAYM''T/ NC (US$)]]-Tabela1[[#This Row],[TOTAL DUE PAYMENT-AS PER FINAL INVOICE US$]] -> 0 | O5: 9811.95 | P5: 56691 | Q5: paga
A6: 144.25 | B6: SIMMONS ARGENTINA | C6: ARGENTINA | D6: 6042 | E6: 45659 | F6: 45659 | G6: 30 days after received | H6: 30 | I6: =Tabela1[[#This Row],[DATA COLETA (ESTIMADA)]]+Tabela1[[#This Row],[days]] -> 45689 | L6: 24931.07 | M6: 24931.07 | N6: =Tabela1[[#This Row],[ADVANCE PAYMENT / FINAL PAYM''T/ NC (US$)]]-Tabela1[[#This Row],[TOTAL DUE PAYMENT-AS PER FINAL INVOICE US$]] -> 0 | O6: 153428.31 | P6: 56529 | Q6: paga | U6: Com paga
A7: 145.25 | B7: FLEX CHILE | D7: 6113 | E7: 45665 | F7: 45665 | G7: 90 Days | H7: 90 | I7: =Tabela1[[#This Row],[DATA COLETA (ESTIMADA)]]+Tabela1[[#This Row],[days]] -> 45755 | L7: 6236.148 | M7: 6236.148 | N7: =Tabela1[[#This Row],[ADVANCE PAYMENT / FINAL PAYM''T/ NC (US$)]]-Tabela1[[#This Row],[TOTAL DUE PAYMENT-AS PER FINAL INVOICE US$]] -> 0 | O7: 41965.93 | P7: 56569 | Q7: paga | R7: Paga - sin documentación de soporte
A8: 145.25 | B8: DIVINO | D8: 6039 | E8: 45695 | F8: 45695 | G8: 50% Pre Payment - 50% After Received | H8: 30 | I8: =Tabela1[[#This Row],[DATA COLETA (ESTIMADA)]]+Tabela1[[#This Row],[days]] -> 45725 | L8: 39447.86 | M8: 39447.86 | N8: =Tabela1[[#This Row],[ADVANCE PAYMENT / FINAL PAYM''T/ NC (US$)]]-Tabela1[[#This Row],[TOTAL DUE PAYMENT-AS PER FINAL INVOICE US$]] -> 0 | O8: =220531.08+10617.6 -> 231148.68 | P8: 56.800/56.801 | Q8: paga
A9: 147.25 | B9: PARAISO DEL ECUADOR | C9: ECUADOR | D9: 5929 | E9: 45660 | F9: 45791 | G9: 60 Days | H9: 60 | I9: =Tabela1[[#This Row],[DATA COLETA (ESTIMADA)]]+Tabela1[[#This Row],[days]] -> 45851 | L9: 1302.84 | M9: 1302.84 | N9: =Tabela1[[#This Row],[ADVANCE PAYMENT / FINAL PAYM''T/ NC (US$)]]-Tabela1[[#This Row],[TOTAL DUE PAYMENT-AS PER FINAL INVOICE US$]] -> 0 | O9: 8017.81 | P9: --- | Q9: cancelar | R9: NF 56.540 cxld (8.017,81)- ESCLARECIDO/ Cancelar
A10: 148.25 | B10: SUPERSPUMA PARAGUAY (SAECA) | D10: 6168 | E10: 45677 | F10: 45677 | G10: Pre Payment - 100% Counter Expedition | H10: 0 | I10: =Tabela1[[#This Row],[DATA COLETA (ESTIMADA)]]+Tabela1[[#This Row],[days]] -> 45677 | L10: 6099.58 | M10: 6099.58 | N10: =Tabela1[[#This Row],[ADVANCE PAYMENT / FINAL PAYM''T/ NC (US$)]]-Tabela1[[#This Row],[TOTAL DUE PAYMENT-AS PER FINAL INVOICE US$]] -> 0 | O10: 37706.53 | P10: 56743 | Q10: paga | R10: PV 5165 / 6043 / 5386 - NF 56.544 clxd
A11: 149.25 | B11: SUNLOCK | C11: CHILE | D11: 4645 | E11: 45660 | F11: 45660 | G11: Pre-payment | H11: 0 | I11: =Tabela1[[#This Row],[DATA COLETA (ESTIMADA)]]+Tabela1[[#This Row],[days]] -> 45660 | L11: 2839.2 | M11: 2839.2 | N11: =Tabela1[[#This Row],[ADVANCE PAYMENT / FINAL PAYM''T/ NC (US$)]]-Tabela1[[#This Row],[TOTAL DUE PAYMENT-AS PER FINAL INVOICE US$]] -> 0 | O11: 17472.72 | P11: 56543 | Q11: paga | R11: NF CXLD
A12: 150.25 | B12: DAVID MORENO VISCARRA | D12: 6142 | E12: 45671 | F12: 45687 | G12: 30 days | H12: 30 | I12: =Tabela1[[#This Row],[DATA COLETA (ESTIMADA)]]+Tabela1[[#This Row],[days]] -> 45717 | L12: 4583.75 | M12: =4213.29+370.46 -> 4583.75 | N12: =Tabela1[[#This Row],[ADVANCE PAYMENT / FINAL PAYM''T/ NC (US$)]]-Tabela1[[#This Row],[TOTAL DUE PAYMENT-AS PER FINAL INVOICE US$]] -> 0 | O12: 26858.94 | P12: 56802 | Q12: paga | R12: pgo $15168,15 /enviado cubre 130.24/150.25/157.25
A13: 151.25 | B13: FLEX CHILE | D13: 4725 / 6114 / 6236 | E13: 45686 | F13: 45686 | G13: 90 Days | H13: 90 | I13: =Tabela1[[#This Row],[DATA COLETA (ESTIMADA)]]+Tabela1[[#This Row],[days]] -> 45776 | L13: 13980.26 | M13: 13980.26 | N13: =Tabela1[[#This Row],[ADVANCE PAYMENT / FINAL PAYM''T/ NC (US$)]]-Tabela1[[#This Row],[TOTAL DUE PAYMENT-AS PER FINAL INVOICE US$]] -> 0 | O13: 82385.67 | P13: 56774 | Q13: paga | R13: Notificado/Pgo 03Jun 13980,26
A14: 152.25 | B14: FLEX CHILE | D14: 6114 | E14: 45716 | F14: 45716 | G14: 90 Days | H14: 90 | I14: =Tabela1[[#This Row],[DATA COLETA (ESTIMADA)]]+Tabela1[[#This Row],[days]] -> 45806 | N14: =Tabela1[[#This Row],[ADVANCE PAYMENT / FINAL PAYM''T/ NC (US$)]]-Tabela1[[#This Row],[TOTAL DUE PAYMENT-AS PER FINAL INVOICE US$]] -> 0 | O14: 47380.3 | P14: 57134 | Q14: Não procede | R14: Pedido nunca foi despachado/devem dar baixa do Sistema (US$8137,03/NF R$47380,3)
A15: 153.25 | B15: SUNLOCK | C15: CHILE | D15: 6309 | E15: 45777 | F15: 45803 | G15: 30 days | H15: 30 | I15: =Tabela1[[#This Row],[DATA COLETA (ESTIMADA)]]+Tabela1[[#This Row],[days]] -> 45833 | L15: 3385.14 | M15: 3385.14 | N15: =Tabela1[[#This Row],[ADVANCE PAYMENT / FINAL PAYM''T/ NC (US$)]]-Tabela1[[#This Row],[TOTAL DUE PAYMENT-AS PER FINAL INVOICE US$]] -> 0 | O15: 15748.19 | P15: 57899 | Q15: paga | R15: cliente notificado 1/7 - sem resposta --25/08 / NF 153- Invoice 157- SWIFT recibido 12/09- PROBLEMAS DE QA
A16: 156.25 | B16: DIVINO | D16: 6353 | E16: 45716 | F16: 45716 | G16: 50% Pre Payment - 50% After Received | H16: 30 | I16: =Tabela1[[#This Row],[DATA COLETA (ESTIMADA)]]+Tabela1[[#This Row],[days]] -> 45746 | L16: 42371.047 | M16: 42371.047 | N16: =Tabela1[[#This Row],[ADVANCE PAYMENT / FINAL PAYM''T/ NC (US$)]]-Tabela1[[#This Row],[TOTAL DUE PAYMENT-AS PER FINAL INVOICE US$]] -> 0 | O16: 246718.14 | P16: 57145 | Q16: paga
A17: 157.25 | B17: DAVID MORENO VISCARRA | D17: 6384 | E17: 45701 | F17: 45726 | G17: 30 days | H17: 30 | I17: =Tabela1[[#This Row],[DATA COLETA (ESTIMADA)]]+Tabela1[[#This Row],[days]] -> 45756 | L17: 10252.8 | M17: 10252.8 | N17: =Tabela1[[#This Row],[ADVANCE PAYMENT / FINAL PAYM''T/ NC (US$)]]-Tabela1[[#This Row],[TOTAL DUE PAYMENT-AS PER FINAL INVOICE US$]] -> 0 | O17: =27860.93+32462.42 -> 60323.35 | P17: 57600/57.144 | Q17: paga | R17: pgo $15168,15 /enviado cubre 130.24/150.25/157.25
A18: 157.25 | B18: SUNLOCK | C18: CHILE | D18: 6309 | E18: 45741 | F18: 45741 | G18: 30 days | H18: 30 | I18: =Tabela1[[#This Row],[DATA COLETA (ESTIMADA)]]+Tabela1[[#This Row],[days]] -> 45771 | L18: 5271.96 | M18: 5271.96 | N18: =Tabela1[[#This Row],[ADVANCE PAYMENT / FINAL PAYM''T/ NC (US$)]]-Tabela1[[#This Row],[TOTAL DUE PAYMENT-AS PER FINAL INVOICE US$]] -> 0 | O18: 24559.87 | P18: 57401 | Q18: paga | R18: pgto 13Jun VALOR DE FRETE:R$ 5.702,75/ NF 57.397 cxld/ não tem pasta
A19: 158.25 | B19: SUPERSPUMA PARAGUAY (SAECA) | D19: 6310 | E19: 45741 | F19: 45741 | G19: Pre Payment - 100% Counter Expedition | H19: 0 | I19: =Tabela1[[#This Row],[DATA COLETA (ESTIMADA)]]+Tabela1[[#This Row],[days]] -> 45741 | L19: 3483.0436 | M19: 3483.0436 | N19: =Tabela1[[#This Row],[ADVANCE PAYMENT / FINAL PAYM''T/ NC (US$)]]-Tabela1[[#This Row],[TOTAL DUE PAYMENT-AS PER FINAL INVOICE US$]] -> 0 | O19: 19993.72 | P19: 57396 | Q19: paga
A20: 159.25 | B20: DIVINO | D20: 6623 / 6561 | E20: 45743 | F20: 45769 | G20: 50% Pre Payment - 50% After Received | H20: 30 | I20: =Tabela1[[#This Row],[DATA COLETA (ESTIMADA)]]+Tabela1[[#This Row],[days]] -> 45799 | L20: 50430.38 | M20: 50430.38 | N20: =Tabela1[[#This Row],[ADVANCE PAYMENT / FINAL PAYM''T/ NC (US$)]]-Tabela1[[#This Row],[TOTAL DUE PAYMENT-AS PER FINAL INVOICE US$]] -> 0 | O20: 295315.24 | P20: 57746 | Q20: paga | R20: PV 6623 / 6561
A21: 159.25 | B21: PARAISO DEL ECUADOR | C21: ECUADOR | D21: 6536 / 6827 | E21: 45761 | F21: 45791 | G21: 60 Days | H21: 60 | I21: =Tabela1[[#This Row],[DATA COLETA (ESTIMADA)]]+Tabela1[[#This Row],[days]] -> 45851 | L21: 29668.52 | M21: 30363.32 | N21: =Tabela1[[#This Row],[ADVANCE PAYMENT / FINAL PAYM''T/ NC (US$)]]-Tabela1[[#This Row],[TOTAL DUE PAYMENT-AS PER FINAL INVOICE US$]] -> 694.8 | O21: 105997.81 | P21: 57673/57.493 | Q21: paga | R21: faturado - 57652 Devolução? R$ 8017,81-Notificado 13/08/ Swift 30.363,32 (180925)- Recbimento -70 (Taxa)-Consolida 159.25+205.25
A22: 160.25 | B22: DIVINO | D22: 6353 /6561 /6039 /6353 | E22: 45754 | F22: 45754 | G22: 50% Pre Payment - 50% After Received | H22: 30 | I22: =Tabela1[[#This Row],[DATA COLETA (ESTIMADA)]]+Tabela1[[#This Row],[days]] -> 45784 | L22: 55384.55 | M22: 55384.55 | N22: =Tabela1[[#This Row],[ADVANCE PAYMENT / FINAL PAYM''T/ NC (US$)]]-Tabela1[[#This Row],[TOTAL DUE PAYMENT-AS PER FINAL INVOICE US$]] -> 0 | O22: =11933.14+262432.92+9160.55+35911.99 -> 319438.6 | P22: 57492/ 57.489/ 57.559/57.558 | Q22: paga
A23: 161.25 | B23: CUBA - David Rosabal Container 1 | D23: 6732 | E23: 45751 | F23: 45800 | G23: 30 - 60 DAYS | H23: 60 | I23: =Tabela1[[#This Row],[DATA COLETA (ESTIMADA)]]+Tabela1[[#This Row],[days]] -> 45860 | J23: 24544.55 | L23: 51274.55 | M23: =33656.36+4500 -> 38156.36 | N23: =Tabela1[[#This Row],[ADVANCE PAYMENT / FINAL PAYM''T/ NC (US$)]]-Tabela1[[#This Row],[TOTAL DUE PAYMENT-AS PER FINAL INVOICE US$]] -> -13118.19 | O23: 287481.02 | P23: 57547/57553/ 57.566 ajuste | Q23: parcial | R23: 2025-Pending-Ajuste Proforma EUROS (46.557,57)-Sinal US4 4.500 / Revisada para USD/Alinhada com DUE/ Wire Transfer recebido (18226,5)- devolvido -Restricciones cambio- Unifica 161.25 & 162.25
A24: 162.25 | B24: CUBA - David Rosabal Container 2 | D24: 6733/6783 /6782 | E24: 45751 | F24: 45800 | G24: 30 - 60 DAYS | H24: 60 | I24: =Tabela1[[#This Row],[DATA COLETA (ESTIMADA)]]+Tabela1[[#This Row],[days]] -> 45860 | J24: 26730 | N24: =Tabela1[[#This Row],[ADVANCE PAYMENT / FINAL PAYM''T/ NC (US$)]]-Tabela1[[#This Row],[TOTAL DUE PAYMENT-AS PER FINAL INVOICE US$]] -> 0 | O24: 149867.09 | P24: 57547 | Q24: parcial | R24: 2025-Pending-Consolida 162.25 con 161.25- Invoice revisada novamente para USD - Detalhes em Ajustes CubaFile
A25: 163.25 | B25: FLEX CHILE | D25: 6752 / 6868 / 6949 | E25: 45754 | F25: 45792 | G25: 90 Days | H25: 90 | I25: =Tabela1[[#This Row],[DATA COLETA (ESTIMADA)]]+Tabela1[[#This Row],[days]] -> 45882 | N25: =Tabela1[[#This Row],[ADVANCE PAYMENT / FINAL PAYM''T/ NC (US$)]]-Tabela1[[#This Row],[TOTAL DUE PAYMENT-AS PER FINAL INVOICE US$]] -> 0 | O25: - | P25: 58048/57.898 | Q25: paga | R25: 6752 / 6868 / 6949; ajustada para 164.25. Ver valores nessa cell
A26: 163.25 | B26: MAXI KING | D26: 6706 | E26: 45790 | F26: 45793 | G26: 25% Advanced - 2 Cuotes 60/90 | H26: 90 | I26: =Tabela1[[#This Row],[DATA COLETA (ESTIMADA)]]+Tabela1[[#This Row],[days]] -> 45883 | L26: 24721.14 | M26: =4970+10000+9721.14+30 -> 24721.14 | N26: =Tabela1[[#This Row],[ADVANCE PAYMENT / FINAL PAYM''T/ NC (US$)]]-Tabela1[[#This Row],[TOTAL DUE PAYMENT-AS PER FINAL INVOICE US$]] -> 0 | O26: =64073.52+75285.87 -> 139359.39 | P26: 58050/57.900 | Q26: paga | R26: parcialmente atendido .-change in original invoice/not doctd- 3 pgs parciales-Swift filed- -$30
A27: 164.25 | B27: DIVINO | D27: 6816 / 6623 | E27: 45756 | F27: 45786 | G27: 50% Pre Payment - 50% After Received | H27: 30 | I27: =Tabela1[[#This Row],[DATA COLETA (ESTIMADA)]]+Tabela1[[#This Row],[days]] -> 45816 | L27: 63969.62 | M27: 63969.62 | N27: =Tabela1[[#This Row],[ADVANCE PAYMENT / FINAL PAYM''T/ NC (US$)]]-Tabela1[[#This Row],[TOTAL DUE PAYMENT-AS PER FINAL INVOICE US$]] -> 0 | O27: =34858.59+328872.65 -> 363731.24 | P27: 57985 / 57.984 | Q27: paga
A28: 164.25 | B28: SEA TRADING (MATERASSI) | C28: PARAGUAY | D28: 6597 | E28: 45758 | F28: 45758 | G28: Pre-payment | H28: 0 | I28: =Tabela1[[#This Row],[DATA COLETA (ESTIMADA)]]+Tabela1[[#This Row],[days]] -> 45758 | L28: 1610.82 | M28: 1610.82 | N28: =Tabela1[[#This Row],[ADVANCE PAYMENT / FINAL PAYM''T/ NC (US$)]]-Tabela1[[#This Row],[TOTAL DUE PAYMENT-AS PER FINAL INVOICE US$]] -> 0 | O28: 9522.36 | P28: 57657 | Q28: paga
A29: 164.25 | B29: FLEX CHILE | D29: 6752 / 6868 / 6949/6816 /6623 | E29: 45777 | F29: 45792 | G29: 90 Days | H29: 90 | I29: =Tabela1[[#This Row],[DATA COLETA (ESTIMADA)]]+Tabela1[[#This Row],[days]] -> 45882 | L29: 8953.43 | M29: 8953.43 | N29: =Tabela1[[#This Row],[ADVANCE PAYMENT / FINAL PAYM''T/ NC (US$)]]-Tabela1[[#This Row],[TOTAL DUE PAYMENT-AS PER FINAL INVOICE US$]] -> 0 | O29: 23579.07 | P29: 58048 | Q29: paga | R29: Swift pago 07/08- PV 6752 / 6868 / 6949- Consolida 164.24+170.25+176.25- Dev. /57.898/57.985/57.984
A30: 165.25 | B30: INMAPOL | D30: 6495 | E30: 45758 | F30: 45758 | G30: Pre-payment | H30: 0 | I30: =Tabela1[[#This Row],[DATA COLETA (ESTIMADA)]]+Tabela1[[#This Row],[days]] -> 45758 | L30: 6438.41 | M30: =5906+532.41 -> 6438.41 | N30: =Tabela1[[#This Row],[ADVANCE PAYMENT / FINAL PAYM''T/ NC (US$)]]-Tabela1[[#This Row],[TOTAL DUE PAYMENT-AS PER FINAL INVOICE US$]] -> 0 | O30: 38060.65 | P30: 57658 | Q30: paga
A31: 166.25 | B31: FLEX CHILE | D31: 6875 | E31: 45754 | F31: 45771 | G31: 90 Days | H31: 90 | I31: =Tabela1[[#This Row],[DATA COLETA (ESTIMADA)]]+Tabela1[[#This Row],[days]] -> 45861 | L31: 2222.72 | M31: 2222.72 | N31: =Tabela1[[#This Row],[ADVANCE PAYMENT / FINAL PAYM''T/ NC (US$)]]-Tabela1[[#This Row],[TOTAL DUE PAYMENT-AS PER FINAL INVOICE US$]] -> 0 | O31: 12642.83 | P31: 57775 | Q31: cancelar | R31: will NOT Charge--Rep. Qualidade. 2.222,72
A32: 167.25 | B32: FLEX CHILE | D32: 6880/ 7178 | E32: 45769 | F32: 45807 | G32: 90 Days | H32: 90 | I32: =Tabela1[[#This Row],[DATA COLETA (ESTIMADA)]]+Tabela1[[#This Row],[days]] -> 45897 | L32: 12665.19 | M32: 12665.19 | N32: =Tabela1[[#This Row],[ADVANCE PAYMENT / FINAL PAYM''T/ NC (US$)]]-Tabela1[[#This Row],[TOTAL DUE PAYMENT-AS PER FINAL INVOICE US$]] -> 0 | O32: - | P32: 58433/58.358 | Q32: paga | R32: 167+168+/ add +400/+200 dos mesmos artigos 19/5 (125.25 amostras)- SWIFT $12665,19 (030925)- Fup -Invoice saida 167.25+168.25+181.25 +189.25 (12.665,19) -
A33: 168.25 | B33: FLEX CHILE | D33: 6880 / 7015 | E33: 45784 | F33: 45814 | G33: 90 Days | H33: 90 | I33: =Tabela1[[#This Row],[DATA COLETA (ESTIMADA)]]+Tabela1[[#This Row],[days]] -> 45904 | N33: =Tabela1[[#This Row],[ADVANCE PAYMENT / FINAL PAYM''T/ NC (US$)]]-Tabela1[[#This Row],[TOTAL DUE PAYMENT-AS PER FINAL INVOICE US$]] -> 0 | O33: - | P33: - | Q33: paga | R33: 167+168+ - inv 167.25 + 168.25 juntas para faturamento -
A34: 171.25 | B34: DIST. CASEROS | D34: 6881 | E34: 45763 | F34: 45806 | G34: 30 days | H34: 30 | I34: =Tabela1[[#This Row],[DATA COLETA (ESTIMADA)]]+Tabela1[[#This Row],[days]] -> 45836 | L34: =13588.23-2458.33 -> 11129.9 | M34: 11335.23 | N34: =Tabela1[[#This Row],[ADVANCE PAYMENT / FINAL PAYM''T/ NC (US$)]]-Tabela1[[#This Row],[TOTAL DUE PAYMENT-AS PER FINAL INVOICE US$]] -> 205.33 | O34: 77365.96 | P34: 58340 | Q34: paga | R34: faturado 29/05 / cliente notiticado/Frete pago em destino ($2.458,33- R$ 14.791,13 /Swift 0508 (11335,23)
A35: 172.25 | B35: DAVID MORENO VISCARRA | D35: 6882 | E35: 45793 | F35: 45798 | G35: Pre-payment | H35: 0 | I35: =Tabela1[[#This Row],[DATA COLETA (ESTIMADA)]]+Tabela1[[#This Row],[days]] -> 45798 | L35: 5543.9 | M35: =5283.16+260.74 -> 5543.9 | N35: =Tabela1[[#This Row],[ADVANCE PAYMENT / FINAL PAYM''T/ NC (US$)]]-Tabela1[[#This Row],[TOTAL DUE PAYMENT-AS PER FINAL INVOICE US$]] -> 0 | O35: 31389.01 | P35: 58293 | Q35: paga | R35: cliente notificado-Swift recibido 14/08-saldo pendiente
A36: 173.25 | B36: DIVINO | D36: 6816 | E36: 45771 | F36: 45839 | G36: 50% Pre Payment - 50% After Received | H36: 30 | I36: =Tabela1[[#This Row],[DATA COLETA (ESTIMADA)]]+Tabela1[[#This Row],[days]] -> 45869 | L36: 0 | M36: 0 | N36: =Tabela1[[#This Row],[ADVANCE PAYMENT / FINAL PAYM''T/ NC (US$)]]-Tabela1[[#This Row],[TOTAL DUE PAYMENT-AS PER FINAL INVOICE US$]] -> 0 | O36: 0 | P36: 58963 | Q36: cancelar | R36: junto com 177.25 y 184.25 - revisar valor único em 184.25
A37: 174.25 | B37: SUNLOCK SPA | C37: CHILE | D37: 6940 | E37: 45772 | F37: 45817 | G37: 30 days | H37: 30 | I37: =Tabela1[[#This Row],[DATA COLETA (ESTIMADA)]]+Tabela1[[#This Row],[days]] -> 45847 | L37: =13702.88+136.8 -> 13839.68 | M37: =13839.68 -> 13839.68 | N37: =Tabela1[[#This Row],[ADVANCE PAYMENT / FINAL PAYM''T/ NC (US$)]]-Tabela1[[#This Row],[TOTAL DUE PAYMENT-AS PER FINAL INVOICE US$]] -> 0 | O37: 67566.51 | P37: 58356/ 58476 (amostra fat) | Q37: paga | R37: ajuste invoice final. Cliente notificado-NF 58355 devolução venda recusada-Swift 17Oct ($13839.68)/paga amostra 121.25
A38: 175.25 | B38: BED TIME | C38: ARGENTINA | D38: 6954 | E38: 45775 | F38: 45800 | G38: 30 days, after customs clearance | H38: 35 | I38: =Tabela1[[#This Row],[DATA COLETA (ESTIMADA)]]+Tabela1[[#This Row],[days]] -> 45835 | L38: 37823.39 | M38: 37823.39 | N38: =Tabela1[[#This Row],[ADVANCE PAYMENT / FINAL PAYM''T/ NC (US$)]]-Tabela1[[#This Row],[TOTAL DUE PAYMENT-AS PER FINAL INVOICE US$]] -> 0 | O38: 215336.13 | P38: 58275 | Q38: paga | R38: Swift pago 21/7 - faturado; ajuste invoice final. | S38: 2025
A39: 176.25 | B39: FLEX CHILE | D39: 6949 | E39: 45776 | F39: 45792 | G39: 90 Days | H39: 90 | I39: =Tabela1[[#This Row],[DATA COLETA (ESTIMADA)]]+Tabela1[[#This Row],[days]] -> 45882 | N39: =Tabela1[[#This Row],[ADVANCE PAYMENT / FINAL PAYM''T/ NC (US$)]]-Tabela1[[#This Row],[TOTAL DUE PAYMENT-AS PER FINAL INVOICE US$]] -> 0 | O39: - | P39: - | Q39: paga | R39: parcialmente atendido- consolida invoice 164.25
A40: 177.25 | B40: DIVINO | D40: 7068 | E40: 45792 | F40: 45839 | G40: 50% Pre Payment - 50% After Received | H40: 30 | I40: =Tabela1[[#This Row],[DATA COLETA (ESTIMADA)]]+Tabela1[[#This Row],[days]] -> 45869 | L40: 0 | M40: 0 | N40: =Tabela1[[#This Row],[ADVANCE PAYMENT / FINAL PAYM''T/ NC (US$)]]-Tabela1[[#This Row],[TOTAL DUE PAYMENT-AS PER FINAL INVOICE US$]] -> 0 | O40: 0 | P40: 58963 | Q40: cancelar | R40: 177.25+173.25+ 184.25 (consolida saida)- valor em 184.25
...

Sheet BASE DADOS CONTATOS
A1: CONEXÃO MALHAS - CONTATOS CLAVES / CLIENTES ATIVOS
A3: Regiao | B3: Sub-regiao | C3: Clientes | D3: Ativos | E3: Inativos | F3: Prospect | G3: Potencial | H3: Estrategicos | I3: Sensiveis | J3: contato | K3: cargo | L3: email | M3: telefone | N3: Observ.
A4: Chile | B4: Santiago | C4: Flex Equipos de Descanso | D4: Sim | E4: - | F4: - | G4: Grande | H4: Sim | I4: Sim | J4: Paulina Mena | K4: Compras | L4: paulina.mena@flex.es | M4: 56 96205 0626 | N4: amostras/ desenvolvimento/OC
A5: Chile | B5: Santiago | C5: Flex Equipos de Descanso | D5: Sim | G5: Grande | H5: Sim | I5: Sim | J5: Danae Briones | K5: Importações | L5: danae.briones@flex.es | M5: +56 9 5514 2584
A6: Chile | B6: Santiago | C6: Flex Equipos de Descanso | D6: Sim | G6: Grande | H6: Sim | I6: Sim | J6: Francesca Seitz | K6: Marketing | L6: francesca.seitz@flex.es | M6: +56 9 3451 9331
A7: Chile | B7: Santiago | C7: Flex Equipos de Descanso | D7: Sim | G7: Grande | H7: Sim | I7: Sim | J7: Angelo Almonacid | K7: Supply | L7: angelo.almonacid@flex.es | M7: +56 9 4400 6214 | N7: Manager of others
A8: Chile | B8: Santiago | C8: Sunlock (Serta) | D8: Sim | E8: - | F8: - | G8: Pequeno | H8: - | I8: - | J8: Juan Carlos Villarroel | K8: Compras | L8: jcvillarroel@sunlock.cl | M8: (+56) 98529-7739
A9: Chile | B9: Santiago | C9: Sunlock (Serta) | D9: Sim | G9: Pequeno | H9: - | I9: - | J9: Felipe San Martin | K9: Socio | L9: fsanmartin@multimetal.cl | M9: +56 9 9939 1194 | N9: Estrategico/ pagamentos
A10: Chile | B10: Santiago | C10: Muebles MPR | D10: Sim | E10: - | F10: - | G10: Pequeno | H10: - | I10: - | J10: Misael | K10: Financeiro | L10: NA | M10: +56 9 5413 0257
A11: Chile | B11: Santiago | C11: Muebles MPR | D11: Sim | G11: Pequeno | H11: - | I11: - | J11: Daniel Carvajal | K11: Socio | L11: mpr.muebleria@gmail.com | M11: +56 9 7977 0882
A12: Paraguai | B12: Asuncao | C12: SuperSpuma | D12: Sim | E12: - | F12: - | G12: Medio | H12: - | I12: - | J12: Leticia Roig | K12: Compras | L12: leticia.roig@superspuma.com.py | M12: +595 985 629024
A13: Paraguai | B13: Asuncao | C13: SuperSpuma | D13: Sim | E13: - | F13: - | G13: Medio | H13: - | I13: - | J13: Maria Laura | K13: Marketing | L13: maria.laura@superspuma.com.py | M13: +595 986 154856
A14: Paraguai | B14: Asuncao | C14: SuperSpuma | D14: Sim | E14: - | F14: - | G14: Medio | H14: - | I14: - | J14: Ruth Sosa | K14: Importações | L14: ruth.sosa@superspuma.com.py | M14: +595 971 889820
A15: Paraguai | B15: Asuncao | C15: Inmapol (Industria de la madera) | D15: Sim | E15: - | F15: - | G15: Pequeno | H15: - | I15: - | J15: Marcos | K15: Socio | L15: madrisa@inmapol.com.py | M15: 595 21 942 599
A16: Paraguai | B16: Asuncao | C16: Inmapol (Industria de la madera) | D16: Sim | E16: - | F16: - | G16: Pequeno | H16: - | I16: - | J16: Alejandro Abraham | K16: Representante | L16: ale@erwinabraham.com | M16: NA | N16: intermediario
A17: Paraguai | B17: Luque | C17: Materassi (Sea Trading) | D17: Sim | E17: - | F17: - | G17: Pequeno | H17: - | I17: - | J17: Alcibiades Greco | K17: Socio | L17: unicornio_py@yahoo.es | M17: 595 982 119084
A18: Paraguai | B18: Luque | C18: Materassi (Sea Trading) | D18: Sim | E18: - | F18: - | G18: Pequeno | H18: - | I18: - | J18: Yessica | K18: Compras | L18: Yessicanuf@gmail.com | M18: NA
A19: Paraguai | B19: Santa Rita | C19: Nature (NM Espuma) | D19: Sim | E19: - | F19: - | G19: Pequeno | H19: - | I19: - | J19: Federico Nuñez | K19: Financeiro | L19: federico@nunez.com.py | M19: +595 983 603791
A20: Paraguai | B20: Santa Rita | C20: Nature (NM Espuma) | D20: Sim | E20: - | F20: - | G20: Pequeno | H20: - | I20: - | J20: Jorge Nuñez | K20: Socio | L20: jorge@nunez.com.py | M20: +595 983 688644
A21: Paraguai | B21: Santa Rita | C21: Nature (NM Espuma) | D21: Sim | E21: - | F21: - | G21: Pequeno | H21: - | I21: - | J21: Susana Diaz | K21: Compras | L21: administracion@nature.com.py | M21: +595 982 795064 | N21: admin
A22: Argentina | B22: Buenos Aires | C22: Simmons Argentina | D22: Sim | E22: - | F22: - | G22: Grande | H22: Sim | I22: Sim | J22: Martin Miller | K22: Representante | L22: comercial@martinmiller.com.ar | M22: +54 9 11 6237-7072 | N22: intermediario
A23: Uruguai | B23: Montevideo | C23: Divino | D23: Sim | E23: - | F23: - | G23: Grande | H23: Sim | I23: Sim | J23: FRANCO MACHAO | K23: Comex | L23: franco.machao@divino.com.uy | M23: + 598 (2) 506.1262
A24: Uruguai | B24: Montevideo | C24: Divino | D24: Sim | E24: - | F24: - | G24: Grande | H24: Sim | I24: Sim | J24: Agustina Vuco | K24: Comex | L24: agustina.vuco@divino.com.uy | M24: +598 98 456 659
A25: Uruguai | B25: Montevideo | C25: Divino | D25: Sim | E25: - | F25: - | G25: Grande | H25: Sim | I25: Sim | J25: Emilia Torres | K25: Comex | L25: emilia.torres@divino.com.uy | M25: +598 98 455 154 | N25: comex@divino.com.uy
A26: Uruguai | B26: Montevideo | C26: Divino | D26: Sim | E26: - | F26: - | G26: Grande | H26: Sim | I26: Sim | J26: Esteban Saibene | K26: Compras | L26: esteban.saibene@divino.com.uy | M26: +598 92 873 272 | N26: Moveis
A27: Uruguai | B27: Montevideo | C27: Divino | D27: Sim | E27: - | F27: - | G27: Grande | H27: Sim | I27: Sim | J27: Federico Durán | K27: Operações | L27: federico.duran@divino.com.uy | M27: +598 99 919 936 | N27: Gte Gral Fabrica
A28: Uruguai | B28: Montevideo | C28: Divino | D28: Sim | E28: - | F28: - | G28: Grande | H28: Sim | I28: Sim | J28: Fernando Rugiero | K28: Compras | L28: fernando.rugiero@divino.com.uy | M28: +598 92 622 679 | N28: Tecido
A29: Uruguai | B29: Montevideo | C29: Divino | D29: Sim | E29: - | F29: - | G29: Grande | H29: Sim | I29: Sim | J29: Francisco Studer | K29: Comex | L29: francisco.studer@divino.com.uy | M29: +598 92 815 133 | N29: Manager of others
A30: Uruguai | B30: Montevideo | C30: Divino | D30: Sim | E30: - | F30: - | G30: Grande | H30: Sim | I30: Sim | J30: Hernán Berro | K30: Supply | L30: hernan.berro@divino.com.uy | M30: +598 98 988 226 | N30: Director
A31: Uruguai | B31: Montevideo | C31: Divino | D31: Sim | E31: - | F31: - | G31: Grande | H31: Sim | I31: Sim | J31: Cecilia Solodilin | K31: Compras | L31: cecilia.solodilin@divino.com.uy | M31: +59825061262 | N31: Asistente de Fernando Rugiero
A32: Uruguai | B32: Montevideo | C32: Polymax | D32: Sim | E32: - | F32: - | G32: Medio | H32: Sim | I32: Sim | J32: Gonzalo Rodriguez | K32: Gerente Gral | L32: grodriguez@polymax.com.uy | M32: +598 2320 2320
A33: Uruguai | B33: Montevideo | C33: Polymax | D33: Sim | E33: - | F33: - | G33: Medio | H33: Sim | I33: Sim | J33: Eliana Garyalde | K33: Asistente Gerencia | L33: asistente.gerencia@polymax.com.uy | M33: +598 94 507 590
A34: Equador | B34: Guayaquil | C34: Productos Paraiso do Ecuador | D34: Sim | E34: - | F34: - | G34: Grande | H34: Sim | I34: - | J34: Diego Perez | K34: Operações | L34: diegoperez@paraiso.com.ec | M34: +593 98 728 8947 | N34: Gte Gral Fabrica
A35: Equador | B35: Guayaquil | C35: Productos Paraiso do Ecuador | D35: Sim | E35: - | F35: - | G35: Grande | H35: Sim | I35: - | J35: Francisco Rivas | K35: Marketing | L35: gerencia.c@paraiso.com.ec | M35: +593 99 440 2827
A36: Equador | B36: Guayaquil | C36: Productos Paraiso do Ecuador | D36: Sim | E36: - | F36: - | G36: Grande | H36: Sim | I36: - | J36: Jose Luis Andrango | K36: Compras | L36: joseandrango@paraiso.com.ec | M36: +593 99 161 0288
A37: Equador | B37: Guayaquil | C37: Productos Paraiso do Ecuador | D37: Sim | E37: - | F37: - | G37: Grande | H37: Sim | I37: - | J37: Joana Ñato | K37: Financeiro | L37: comexuio@paraiso.com.ec | M37: +593 99 784 7907 | N37: pagamento
A38: Equador | B38: Guayaquil | C38: Productos Paraiso do Ecuador | D38: Sim | E38: - | F38: - | G38: Grande | H38: Sim | I38: - | J38: Maria José Camacho | K38: Comex | L38: comexgye@paraiso.com.ec | M38: +593 99 949 4115
A39: Equador | B39: Guayaquil | C39: Productos Paraiso do Ecuador | D39: Sim | E39: - | F39: - | G39: Grande | H39: Sim | I39: - | J39: René Cortes | K39: Gerente Gral | L39: gerenciagye@paraiso.com.ec | M39: +593 99 377 7690 | N39: pagamento
A40: Equador | B40: Cuenca | C40: Colineal | D40: Sim | E40: - | F40: - | G40: Medio | H40: - | I40: - | J40: Gabriela Briones | K40: Marketing | L40: gabrielabriones@colinealcorp.com | M40: +593 99 530 6517
A41: Equador | B41: Cuenca | C41: Colineal | D41: Sim | E41: - | F41: - | G41: Medio | H41: - | I41: - | J41: Patricio Culquer | K41: Compras | L41: patricioculquer@colinealcorp.com | M41: +593 99 847 9284
...

Sheet SUMMARY
A1: FLUXO DE CREDITO | S1: PENDING VALUES | AK1: DEADLINES - DATA - VALUE
S2: Anos | T2: (Todas) | AK2: STATUS PGTO | AL2: (Varios elementos)
A3: Suma de TOTAL DUE BALANCE (US$) | B3: STATUS | S3: STATUS PGTO | T3: (Varios elementos)
A4: CLIENTES | B4: cancelar | C4: Devolução | D4: futura | E4: Não procede | F4: paga | G4: parcial | H4: pendente | I4: NC | J4: on hold | K4: Total general (DUE) | AL4: STATUS
A5: BED TIME | D5: -83980 | F5: 0 | K5: -83980 | S5: Suma de TOTAL DUE BALANCE (US$) | T5: mês | AL5: Suma de DATA VENCIMENTO/ | AN5: Suma de TOTAL DUE BALANCE (US$) | AP5: Total Suma de DATA VENCIMENTO/ | AQ5: Total Suma de TOTAL DUE BALANCE (US$)
A6: COLCHONES DEL PARAGUAY | D6: -3685 | F6: 0 | K6: -3685 | S6: CLIENTES | T6: ene | U6: mar | V6: jul | W6: ago | X6: sep | Y6: oct | Z6: nov | AA6: dic | AB6: Total general | AL6: 2025 | AM6: 2026 | AN6: 2025 | AO6: 2026
A7: CUBA - David Rosabal Container 1 | G7: -13118.19 | K7: -13118.19 | S7: CUBA - David Rosabal Container 1 | V7: -13118.19 | AB7: -13118.19 | AK7: CLIENTES
A8: CUBA - David Rosabal Container 2 | G8: 0 | K8: 0 | S8: CUBA - David Rosabal Container 2 | V8: 0 | AB8: 0 | AK8: CUBA - David Rosabal Container 1 | AL8: 45860 | AN8: -13118.19 | AP8: 45860 | AQ8: -13118.19
A9: DAVID MORENO VISCARRA | F9: 0 | K9: 0 | S9: FRAZADAS ARTESANALES (LA GRANDE) | T9: -144.995 | AB9: -144.995 | AK9: CUBA - David Rosabal Container 2 | AL9: 45860 | AN9: 0 | AP9: 45860 | AQ9: 0
A10: DIST. CASEROS | F10: 205.33 | K10: 205.33 | S10: SUNLOCK SPA | U10: 8898.93 | V10: -8688.48 | AA10: -16234.12 | AB10: -16023.67 | AK10: FRAZADAS ARTESANALES (LA GRANDE) | AM10: 46028 | AO10: -144.995 | AP10: 46028 | AQ10: -144.995
A11: DIVINO | B11: 0 | F11: 0 | K11: 0 | S11: YP S.A. (Grupo Suenolar) | X11: -37 | AB11: -37 | AK11: SUNLOCK SPA | AM11: 230922 | AO11: -16023.67 | AP11: 230922 | AQ11: -16023.67
A12: FLEX CHILE | B12: 0 | C12: 0 | D12: -24285.93 | E12: 0 | F12: -0.03 | K12: -24285.96 | S12: TEC NIPONA PERÚ (AMAZHEL) | W12: -229.32 | AB12: -229.32 | AK12: YP S.A. (Grupo Suenolar) | AM12: 46268 | AO12: -37 | AP12: 46268 | AQ12: -37
A13: FRAZADAS ARTESANALES (LA GRANDE) | F13: 0 | G13: -144.995 | K13: -144.995 | S13: PARAISO DEL ECUADOR | V13: -8166.7 | Y13: -35 | Z13: -44.12 | AB13: -8245.82 | AK13: TEC NIPONA PERÚ (AMAZHEL) | AM13: 46245 | AO13: -229.32 | AP13: 46245 | AQ13: -229.32
A14: IMPORTADORA TERRA (MOVELPRO SRL) | F14: 514.7 | K14: 514.7 | S14: Total general | T14: -144.995 | U14: 8898.93 | V14: -29973.37 | W14: -229.32 | X14: -37 | Y14: -35 | Z14: -44.12 | AA14: -16234.12 | AB14: -37798.995 | AK14: PARAISO DEL ECUADOR | AL14: 91936 | AM14: 46224 | AN14: -79.12 | AO14: -8166.7 | AP14: 138160 | AQ14: -8245.82
A15: INDUCOL | F15: -0.01 | K15: -0.01 | AK15: Total general (DUE) | AL15: 183656 | AM15: 415687 | AN15: -13197.31 | AO15: -24601.685 | AP15: 599343 | AQ15: -37798.995
A16: INMAPOL | F16: 0 | K16: 0
A17: LAMITEX S.A. | F17: 0 | K17: 0
A18: MAXI KING | F18: 0 | K18: 0
A19: MULTIESPUMAS VISCARRA | D19: -12400.4 | F19: 0 | K19: -12400.4
A20: SEA TRADING (MATERASSI) | F20: 0 | K20: 0
A21: SERVAN EXPORTADORA DE MANUFACTURADOS LTDA (ABBA) | F21: 0 | K21: 0
A22: SIMMONS ARGENTINA | F22: 0 | K22: 0
A23: SPRINGWALL - VAZQUEZ SACII | F23: 0 | K23: 0
A24: SUNLOCK | F24: 0 | K24: 0
A25: SUNLOCK SPA | F25: 18642.4 | G25: 210.45 | H25: -16234.12 | K25: 2618.73
A26: SUPERSPUMA PARAGUAY (SAECA) | F26: 0 | K26: 0
A27: YP S.A. (Grupo Suenolar) | F27: 0 | G27: -37 | K27: -37
A28: LIMANSKY S.S. | D28: -79126.937 | F28: 0 | I28: -735.68 | K28: -79862.617
A29: TEXTIL FIBREX | F29: -79 | K29: -79
A30: POLYMAX EL GALO | D30: -19888.12 | F30: 256.77 | K30: -19631.35
A31: INDUSTRIAL REGAL | F31: 0 | K31: 0
A32: AGT - AMERICAN GARMENT | J32: -67760 | K32: -67760
A33: TEC NIPONA PERÚ (AMAZHEL) | G33: -229.32 | K33: -229.32
A34: COLOR LIVING | D34: -65775.51 | K34: -65775.51
A35: MANTAHUE SPA | F35: 0 | K35: 0
A36: ATLAS EAS | F36: 0 | K36: 0
A37: PARAISO DEL ECUADOR | B37: 0 | F37: 694.8 | G37: -79.12 | H37: -8166.7 | K37: -7551.02
A38: COLCHONES ESPUMIX (GOVER SPA) | G38: -24444.88 | K38: -24444.88
A39: YP S.A. (SUEÑOLAR) | D39: -9600 | K39: -9600
A40: Total general (DUE) | B40: 0 | C40: 0 | D40: -298741.9 | E40: 0 | F40: 20234.96 | G40: -37843.055 | H40: -24400.82 | I40: -735.68 | J40: -67760 | K40: -409246.49

Sheet INMAPOL

Sheet notificação clientes
B1: GESTÃO DE PAGAMENTO | D1: =TODAY() -> 46296 | I1: revisar abril- fim do mês
B3: INVOICE | C3: CUSTOMER | D3: TOTAL VALUE INVOICE US$ | E3: ADVANCE PAYMENT /CREDIT NOTE US$ | F3: TOTAL DUE BALANCE US$ | G3: DUE MONTH | H3: STATUS | I3: NOTIFICATION DATE/ EMAILs | J3: OBSERV.
B4: 221.25 | C4: LAMITEX S.A. | D4: 25047.07 | E4: =23905+1142.07 -> 25047.07 | F4: =Tabela13[[#This Row],[TOTAL VALUE INVOICE US$]]-Tabela13[[#This Row],[ADVANCE PAYMENT /CREDIT NOTE US$]] -> 0 | G4: PAGA | H4: PAGA | I4: 46076 | J4: Pending - Notificado- SWIFT 24/02 ($23905) - Saldo pendiente
B5: 220.25 | C5: SUNLOCK SPA | D5: =15772.24+346.92 -> 16119.16 | E5: =4929.86+5597.15+5592.15 -> 16119.16 | F5: =Tabela13[[#This Row],[TOTAL VALUE INVOICE US$]]-Tabela13[[#This Row],[ADVANCE PAYMENT /CREDIT NOTE US$]] -> 0 | G5: JAN/26 | H5: PAGA | I5: 04/02/2026 - Abril - consolidado 06/04 (WA CR) | J5: Pending - Notificado (consolidado)
B6: 217.25 | C6: FLEX CHILE | D6: 6482.4 | F6: =Tabela13[[#This Row],[TOTAL VALUE INVOICE US$]]-Tabela13[[#This Row],[ADVANCE PAYMENT /CREDIT NOTE US$]] -> 6482.4 | G6: PAGA | H6: PAGA | I6: 46121 | J6: pending - notificado
B7: 216.25 | C7: DIVINO | D7: 20124.81 | E7: =11502.5+8622.31 -> 20124.81 | F7: =Tabela13[[#This Row],[TOTAL VALUE INVOICE US$]]-Tabela13[[#This Row],[ADVANCE PAYMENT /CREDIT NOTE US$]] -> 0 | G7: PAGA | H7: PAGA | J7: Fechamento jan26
B8: 215.25 | C8: POLYMAX | D8: 13678.46 | E8: =3633.73+10044 -> 13677.73 | F8: =Tabela13[[#This Row],[TOTAL VALUE INVOICE US$]]-Tabela13[[#This Row],[ADVANCE PAYMENT /CREDIT NOTE US$]] -> 0.73 | G8: FEB/26 | H8: PAGA | I8: 03/03/2026 - Abril - consolidado 06/04 (WA CR)/1004 | J8: Ver esquema de pgos
B9: 212.25 | C9: FRAZADAS ARTESANALES (LA GRANDE) | D9: 44228.245 | E9: 44083.25 | F9: =Tabela13[[#This Row],[TOTAL VALUE INVOICE US$]]-Tabela13[[#This Row],[ADVANCE PAYMENT /CREDIT NOTE US$]] -> 144.995 | G9: JAN/26 | H9: PARCIAL | I9: 25/02/2026 -nunca respondeu sobre saldo pendiente | J9: Pending - swift final 22/12/25 - valor inferior notificado (25/02)
B10: 211.25 | C10: SUPERSPUMA PARAGUAY (SAECA) | D10: 6552 | F10: =Tabela13[[#This Row],[TOTAL VALUE INVOICE US$]]-Tabela13[[#This Row],[ADVANCE PAYMENT /CREDIT NOTE US$]] -> 6552 | G10: PAGA | H10: PAGA | J10: F-UP Faturamento
B11: 211.25 | C11: SUPERSPUMA | D11: 19504.93 | E11: 19504.93 | F11: =Tabela13[[#This Row],[TOTAL VALUE INVOICE US$]]-Tabela13[[#This Row],[ADVANCE PAYMENT /CREDIT NOTE US$]] -> 0 | G11: PAGA | H11: PAGA | J11: Notificar antes de férias coletivas
B12: 210.25 | C12: SUNLOCK SPA | D12: 13908.91 | E12: ='GESTAO CREDITO E PAGAMENTOS'!M70 -> 18900.77 | F12: =Tabela13[[#This Row],[TOTAL VALUE INVOICE US$]]-Tabela13[[#This Row],[ADVANCE PAYMENT /CREDIT NOTE US$]] -> -4991.86 | G12: PAGA | H12: PAGA | I12: 15/01 - 04/02 | J12: PAGO Pending - Notificado (consolida 209 + 210.25)- PARTE PGO SWIFT 23/03- saldo pendiente- Pago 24/04
B13: 208.25 | C13: FLEX CHILE | D13: 4288.53 | F13: =Tabela13[[#This Row],[TOTAL VALUE INVOICE US$]]-Tabela13[[#This Row],[ADVANCE PAYMENT /CREDIT NOTE US$]] -> 4288.53 | G13: PAGA | H13: PAGA
B14: 206.25 | C14: FLEX CHILE | D14: 2826 | E14: 2826 | F14: =Tabela13[[#This Row],[TOTAL VALUE INVOICE US$]]-Tabela13[[#This Row],[ADVANCE PAYMENT /CREDIT NOTE US$]] -> 0 | G14: PAGA | H14: PAGA | J14: Fechamento jan26
B15: 205.25 | C15: PARAÍSO DEL ECUADOR | D15: 738.92 | E15: 694.8 | F15: =Tabela13[[#This Row],[TOTAL VALUE INVOICE US$]]-Tabela13[[#This Row],[ADVANCE PAYMENT /CREDIT NOTE US$]] -> 44.12 | G15: PAGA | H15: PAGA | I15: 13/11/2025 - 24/11 - 26/11 | J15: Notificado - pending - 192.25 + saldo 205.25 ($42,12)
B16: 204.25 | C16: COLCHONES PRINCE | D16: =6554.95 -> 6554.95 | E16: 2000 | F16: =Tabela13[[#This Row],[TOTAL VALUE INVOICE US$]]-Tabela13[[#This Row],[ADVANCE PAYMENT /CREDIT NOTE US$]] -> 4554.95 | G16: PAGA | H16: PAGA | I16: 45987 | J16: Notificado - invoices consolidadas 204.25 +219.25
B17: 201.25 | C17: SERVAN EXPORTADORA DE MANUFACTURADOS LTDA (ABBA) | D17: 29893.05 | E17: 5310 | F17: =Tabela13[[#This Row],[TOTAL VALUE INVOICE US$]]-Tabela13[[#This Row],[ADVANCE PAYMENT /CREDIT NOTE US$]] -> 24583.05 | G17: finalizado | H17: PAGA | I17: Feito boleto Vence 20/11 | J17: Notificar com fechamento Outubro-Faturamento em R$ - inclui frete (R$2.483,07 / Dif vs cotado)
B18: 200.25 | C18: MULTIESPUMAS VISCARRA | D18: 16624.3 | E18: 16624.3 | F18: =Tabela13[[#This Row],[TOTAL VALUE INVOICE US$]]-Tabela13[[#This Row],[ADVANCE PAYMENT /CREDIT NOTE US$]] -> 0 | G18: PAGA | H18: PAGA | I18: 13/11/2025 - 24/11 - 10/12 | J18: Pending - Notificado
B19: 199.25 | C19: SUPERSPUMA PARAGUAY SAECA | D19: 14004.62 | E19: 0 | F19: =Tabela13[[#This Row],[TOTAL VALUE INVOICE US$]]-Tabela13[[#This Row],[ADVANCE PAYMENT /CREDIT NOTE US$]] -> 14004.62 | G19: PAGA | H19: PAGA | I19: 45974 | J19: Pago 02/10/25 - Copia Swift enviada pelo cliente 13/11
B20: 198.25 | C20: SIMMONS ARG | D20: 33840.5 | E20: 0 | F20: =Tabela13[[#This Row],[TOTAL VALUE INVOICE US$]]-Tabela13[[#This Row],[ADVANCE PAYMENT /CREDIT NOTE US$]] -> 33840.5 | G20: PAGA | H20: PAGA | J20: Notificar com fechamento novembro- Notificaciones serán hechas x F&A
B21: 192.25 | C21: PARAÍSO DEL ECUADOR | D21: 12464.3 | E21: 12429.3 | F21: =Tabela13[[#This Row],[TOTAL VALUE INVOICE US$]]-Tabela13[[#This Row],[ADVANCE PAYMENT /CREDIT NOTE US$]] -> 35 | G21: PAGA | H21: PAGA | I21: 13/11/2025 - 24/11 - 26/11 | J21: Notificado - pending
B22: 191.25 | C22: BED TIME | D22: 43413.09 | E22: 43413.09 | F22: =Tabela13[[#This Row],[TOTAL VALUE INVOICE US$]]-Tabela13[[#This Row],[ADVANCE PAYMENT /CREDIT NOTE US$]] -> 0 | G22: PAGA | H22: PAGA | J22: Swift recibido 03/02
B23: 187.25 final | C23: POLYMAX | D23: 1773.88 | F23: =Tabela13[[#This Row],[TOTAL VALUE INVOICE US$]]-Tabela13[[#This Row],[ADVANCE PAYMENT /CREDIT NOTE US$]] -> 1773.88 | G23: JAN/26 | H23: PAGA | I23: 15/01/2026 - 23/02- 03/03 | J23: Ver esquema de pgos
B24: 187.25 | C24: POLYMAX | D24: =30596 -> 30596 | F24: =Tabela13[[#This Row],[TOTAL VALUE INVOICE US$]]-Tabela13[[#This Row],[ADVANCE PAYMENT /CREDIT NOTE US$]] -> 30596 | G24: NOV/25 | H24: PAGA | I24: 15/01/2026 - 23/02 - 03/03 | J24: Pending Notificado - enviar consolidado c/complemento (31.406,39+1,773,88)-saldo despues de carnaval/ Nvo Swift 18Mar- esquema de abonos semanales (fup_)
B25: 180.25 | C25: SUNLOCK SPA | D25: 4734.94 | E25: =3385.14+1349.8 -> 4734.94 | F25: =Tabela13[[#This Row],[TOTAL VALUE INVOICE US$]]-Tabela13[[#This Row],[ADVANCE PAYMENT /CREDIT NOTE US$]] -> 0 | G25: PAGA | H25: PAGA | I25: ago-set- 06/11 - 26/11 - 10/12 - 16/12 - 15/01 -04/02 | J25: SWIFT 23/02
B26: 175.25 | C26: BED TIME | D26: =VLOOKUP(Tabela13[[#This Row],[INVOICE]],'GESTAO CREDITO E PAGAMENTOS'!A$4:R145,11,0) -> 0 | E26: 0 | F26: ='GESTAO CREDITO E PAGAMENTOS'!L34 -> 11129.9 | G26: finalizado | H26: PAGA | I26: paga | J26: email s/ resposta 15/7- PAGA
B27: 174.25 | C27: SUNLOCK SPA | D27: =VLOOKUP(Tabela13[[#This Row],[INVOICE]],'GESTAO CREDITO E PAGAMENTOS'!A$4:R143,11,0) -> 0 | E27: 0 | F27: ='GESTAO CREDITO E PAGAMENTOS'!L33 -> 0 | G27: finalizado | H27: PAGA | I27: 01/07/2025 - 16/07 - 28/07- 05/08 - 06/08-25/08-10/09 | J27: Paga - saldo paga amostras 121.25
B28: 172.25 | C28: DAVID MORENO VISCARRA | D28: 5543.9 | E28: =5283.16+260.74 -> 5543.9 | F28: ='GESTAO CREDITO E PAGAMENTOS'!L30 -> 6438.41 | G28: finalizado | H28: PAGA | I28: 01/07/2025 - 28/07 - 06/08 | J28: Swift recibido 14/08-saldo pendiente recbido 29/08 pago
B29: 171.25 | C29: DIST. CASEROS | D29: =VLOOKUP(Tabela13[[#This Row],[INVOICE]],'GESTAO CREDITO E PAGAMENTOS'!A$4:R146,11,0) -> 0 | E29: 0 | F29: ='GESTAO CREDITO E PAGAMENTOS'!L35 -> 5543.9 | G29: finalizado | H29: PAGA | I29: paga | J29: pagó - swift 05082025 pagA
B30: 165.25 | C30: INMAPOL (Industria de la Madera y el Poliuretano) | D30: 6438.41 | E30: 5906 | F30: ='GESTAO CREDITO E PAGAMENTOS'!L25 -> 0 | G30: finalizado | H30: PAGA | I30: 45764 | J30: Recibido Swift Saldo 28/4. Solicita relatorio comisiones pendientes/rqtd Luciano/ OK - pago
B31: 164.25 | C31: MATERASSI (SEA TRADING) | D31: 1610.82 | E31: 0 | F31: ='GESTAO CREDITO E PAGAMENTOS'!L26 -> 24721.14 | G31: finalizado | H31: PAGA | I31: 45764 | J31: Envio CNPJ- Saldo recebido- email confirmando CR/ OK pago
B32: 161.25+162.25 | C32: CUBA 1 - CUBA 2 | D32: 51274.55 | E32: 38156.36 | F32: =Tabela13[[#This Row],[TOTAL VALUE INVOICE US$]]-Tabela13[[#This Row],[ADVANCE PAYMENT /CREDIT NOTE US$]] -> 13118.19 | G32: JUL/25 | H32: PARCIAL | I32: F-up restrição de cambio-trato direto F&A-CR | J32: Pending - pagos parciais / restrição cambio/ consolida 161.25 + 162.25
B33: 159.25 | C33: PARAÍSO DEL ECUADOR | D33: 29668.52 | E33: 29668.52 | F33: ='GESTAO CREDITO E PAGAMENTOS'!L36 -> 0 | G33: PAGA | H33: PAGA | I33: 13/08, 25/08, 27/08, 03/09-10/09 | J33: paga Swift 18sep
B34: 157.25 | C34: INDUSTRIAS MORENO (HEAVEN) | D34: 10252.8 | E34: 0 | F34: ='GESTAO CREDITO E PAGAMENTOS'!L24 -> 0 | G34: finalizado | H34: PAGA | I34: 45764 | J34: F-up 24/04- sem novos comentários/ Ok - pago
B35: 157.25 | C35: DAVID MORENO VISCARRA | D35: =VLOOKUP(Tabela13[[#This Row],[INVOICE]],'GESTAO CREDITO E PAGAMENTOS'!A4:R19,11,0) -> 0 | E35: 0 | F35: ='GESTAO CREDITO E PAGAMENTOS'!L28 -> 1610.82 | G35: finalizado | H35: PAGA | I35: 45799 | J35: Ok - pago de US$ 15168,15 (3jun25)
B36: 157.25 | C36: SUNLOCK | D36: 5271.96 | E36: 5271.96 | F36: ='GESTAO CREDITO E PAGAMENTOS'!L29 -> 8953.43 | G36: finalizado | H36: PAGA | I36: 45799 | J36: Ok - pago de US$ 5,271,96 (13jun25)
B37: 153.25 | C37: SUNLOCK | D37: =VLOOKUP(Tabela13[[#This Row],[INVOICE]],'GESTAO CREDITO E PAGAMENTOS'!A$4:R143,11,0) -> 0 | E37: 0 | F37: ='GESTAO CREDITO E PAGAMENTOS'!L32 -> 12665.19 | G37: finalizado | H37: PAGA | I37: 01/07/2025 - 16/07 - 28/07- 05/08 - 06/08-25/08 | J37: Pago
B38: 152.25 | C38: FLEX CHILE | D38: 8137.03 | E38: 0 | F38: ='GESTAO CREDITO E PAGAMENTOS'!L31 -> 2222.72 | G38: finalizado | H38: PAGA | I38: 45839 | J38: email- cobrança não procede; pedido nunca foi despachado-devera ser dado de baixa do sist.
B39: 151.25 | C39: FLEX CHILE | D39: =VLOOKUP(Tabela13[[#This Row],[INVOICE]],'GESTAO CREDITO E PAGAMENTOS'!A3:R18,11,0) -> 0 | E39: 0 | F39: ='GESTAO CREDITO E PAGAMENTOS'!L27 -> 63969.62 | G39: finalizado | H39: PAGA | I39: 45799 | J39: pgo confirmado 03Jun/ OK pago
B40: 150.25 | C40: INDUSTRIAS MORENO (HEAVEN) | D40: 4213.29 | E40: 0 | F40: ='GESTAO CREDITO E PAGAMENTOS'!L23 -> 51274.55 | G40: finalizado | H40: PAGA | I40: 45764 | J40: F-up 24/04- sem novos comentários/ Ok - pago
B41: 026.26 + 026.26 C | C41: IND REGAL | D41: 39750 | F41: =Tabela13[[#This Row],[TOTAL VALUE INVOICE US$]]-Tabela13[[#This Row],[ADVANCE PAYMENT /CREDIT NOTE US$]] -> 39750 | G41: AGO/26 | H41: PAGA | I41: Esperar despacho y facturación (atraso) | J41: F-UP Faturamento
...

Sheet SUNLOCK SPA -flujo crédito1906 
A1: GESTIÓN DE CRÉDITO Y PAGOS - 2025 / 2026 | D1: =TODAY() -> 46296
S3: =SUM(I6:I8)-K6 -> 31030.95
A4: PROFORMA-INVOICE (EXPORT.) | B4: CLIENTE | C4: N° ORDEN | D4: FECHA PROFORM | E4: FECHA COLECTA | F4: TERMINO PAGO | G4: days | H4: FECHA VENCIMENTO/ DEADLINE | I4: TOTAL A PAGAR SEGÚN INVOICE US$ | J4: ANTICIPO (US$) | K4: NOTA CREDITO US$ | L4: PAGO FINAL US$ | M4: TOTAL SALDO DEBIDO HOY (US$) | N4: STATUS PAGO | O4: FECHA DE PAGO | P4: DIAS ATRASO | Q4: OBSERV. | S4: pagos 1er ac. | T4: pagos 2do ac
A5: 174.25 | B5: SUNLOCK SPA | C5: 6940 | D5: 45772 | E5: 45817 | F5: 30 days | G5: 30 | H5: 45847 | I5: 13839.68 | L5: 13839.68 | M5: =SUM(J5:L5)-I5 -> 0 | N5: paga | O5: 45947 | P5: =O5-H5 -> 100 | Q5: SWIFT 17Oct POR $13.839,68 | S5: 14591.42 | T5: 6575.25
A6: 180.25 | B6: SUNLOCK SPA | C6: 7173 | D6: 45805 | E6: 45855 | F6: 30 days | G6: 30 | H6: 45885 | I6: 4734.94 | K6: 3385.14 | L6: 14591.42 | M6: =SUM(J6:L6)-I6 -> 13241.62 | N6: paga | O6: 46076 | P6: =O6-H6 -> 191 | Q6: SWIFT 23/02 por $14.591,42 - aplicação NC 3385,14 | S6: 5597.15
A7: 209.25 + 210.25 | B7: SUNLOCK SPA | C7: 8569/8798/8609 | D7: 45937 | E7: 45968 | F7: 30 days | G7: 30 | H7: 45998 | I7: 13908.91 | J7: =M6 -> 13241.62 | L7: 5659.15 | M7: =SUM(J7:L7)-I7 -> 4991.86 | N7: paga | O7: 46136 | P7: =O7-H7 -> 138 | Q7: Saldo anterior ($13.241,62) + SWIFT 24/04 ($5659,15) | S7: 5597.15
A8: 220.25 © | B8: SUNLOCK SPA | C8: 9030 /9035 | D8: 45985 | E8: 46010 | F8: 30 days | G8: 30 | H8: 46040 | I8: =15772.24 -> 15772.24 | J8: =M7 -> 4991.86 | L8: =5597.15+5592.15 -> 11189.3 | M8: =SUM(J8:L8)-I8 -> 408.92 | N8: paga | O8: 46191 | P8: =O8-H8 -> 151 | Q8: saldo anterior (4.991,86) + SWIFT 01/06 (5597,15) +SWIFT 18/06 ($5.592,15) | S8: 5659.15
A9: 003.26+ 005.26 + 007.26 | B9: SUNLOCK SPA | C9: 9157/9177/9207 | D9: 46010 | E9: 46073 | F9: 30 days | G9: 30 | H9: 46103 | I9: 18182.65 | J9: =408.92 -> 408.92 | L9: =5659.15+21013.51 -> 26672.66 | M9: =SUM(J9:L9)-I9 -> 8898.93 | N9: paga | O9: 46283 | P9: =O9-H9 -> 180 | Q9: Saldo anterior $408,91 + SWIFT 12/08 ($5.659,15)+SWIFT 18/09 $21.013,51 | S9: =SUM(S5:S8) -> 31444.87 | T9: =SUM(T5:T8) -> 6575.25
A10: 011.26 | B10: SUNLOCK SPA | C10: 9522 | D10: 46077 | E10: 46140 | F10: 30 days | G10: 30 | H10: 46230 | I10: 24162.66 | J10: =8898.93+6575.25 -> 15474.18 | M10: =SUM(J10:L10)-I10 -> -8688.48 | N10: parcial | O10: 46146 | P10: =O10-H10 -> -84 | Q10: Incluye frete |saldo sobrante anterior ($8.898,93)+ SWIFT 04/05 $6.575,25 | S10: =S3-S9 -> -413.92
A11: 032.26* | B11: SUNLOCK SPA | C11: 10497 | D11: 46182 | E11: 46293 | F11: 30 days | H11: 46293 | I11: 16234.12 | M11: =SUM(J11:L11)-I11 -> -16234.12 | N11: pendente | O11: 46293 | P11: =O11-H11 -> 0 | Q11: Fup pgtos (pedido on hold será liberado 28/09 )|inclui frete
L12: Total | M12: =SUM(M10:M11) -> -24922.6
A14: **pedido estuvo on hold-ya despachado 22/09
A18: 1) *Invoices antiguas 180.25/209.25/210.25 /220.25 (deuda de $31.030,95) - 1er Acuerdo (19marzo) de pagar en 6 cuotas de USD | K18: =SUM(I6:I8)-K6 -> 31030.95 | L18: =K18/6 -> 5171.825
A20: Esquema de pagos: | B20: Pago | C20: Dif | D20: Index | E20: balance hoy
A21: 46136 | B21: 5597.15
A22: 46174 | B22: =5597.15 -> 5597.15
A23: 46191 | B23: 5592.15 | E23: =K18-(SUM(B21:B23)) -> 14244.5
A24: 46246 | B24: 5659.15
A26: 2)**Última Invoice 011.26 | B26: =I10 -> 24162.66 | C26: - Condiciones de pago especiales(29/4/26) > | H26: 33% anticipado /33% 30d /33% 60d
A28: Esquema de pagos: | B28: Pago | C28: Dif. | D28: Index | E28: Invoice | H28: Observ. | I28: Balance
A29: 46146 | B29: 6575.25 | D29: =B29/24162.66 -> 0.27212443 | E29: 011.26 | H29: 1er Abono | I29: =I10-B29 -> 17587.41
A30: 46179 | H30: atraso
A31: 46210 | H31: atraso
A34: 3) Nueva propuesta de pago colocada por el cliente via email (03/09/2026) - En proceso de aprobación interna
A36: Propuesta :
A37: Con Fecha 04/09/2026 se paga USD 17.235,78 ( Orden Fabricada )
A38: Quedando un Saldo de USD 30.110,90, de este saldo se pagan USD 3.777,73 Mensual hasta Diciembre, | N38: 47346.69
A39: sumando estos 4 meses nos da USD 15.110,92 y Finalmente en Diciembre se paga el Saldo Final de USD 15.000 . | M39: - | N39: 17235.78 | O39: =N38-N39 -> 30110.91 | P39: sep | Q39: =17235.78+3777.73 -> 21013.51
M40: - | N40: 4x3777,73 | O40: =4*3777.73 -> 15110.92 | P40: sep/oct/nov/dic
A41: Propuesta Interna (04/09) | O41: =O39-O40 -> 14999.99 | P41: dic | Q41: =15000+3777.73 -> 18777.73
A42: USD 17.235,78 correspondientes a la orden fabricada; y | P42: *contraints (sep & dec)
A43: USD 15.000,00 como amortización de la deuda pendiente.
A44: saldo restante de USD 15.110,90 podríamos mantenerlo dentro de un calendario de pagos en 6 cuotas. Hasta marzo de 2027

Sheet POLYMAX -flujo de crédito 1805
A1: POLYMAX EL GALO | E1: =TODAY() -> 46296
A4: INVOICE (EXPORT.) | B4: CUSTOMER | C4: ORDER NBR | D4: DATA PROFORM-INVOICE | E4: DATA COLETA (ESTIMADA) | F4: TERMINO PAGO | G4: FECHA VENCIMENTO/ DEADLINE | H4: TOTAL A PAGAR SEGÚN INVOICE US$ | I4: ANTICIPO (US$) | J4: NOTA CREDITO US$ | K4: ABONOS US$ | L4: TOTAL CREDITOS US$ | M4: TOTAL SALDO DEBIDO HOY (US$) | N4: STATUS PAGO | O4: FECHA DE PAGO | P4: DIAS ATRASO | Q4: OBSERV.
A5: 187.25 | B5: POLYMAX EL GALO | C5: 7523/8302 | D5: 45848 | E5: 45917 | F5: 60 days | G5: 45977 | H5: =30596 -> 30596 | I5: 15000 | K5: =7978.5+6978.5+6965 -> 21922 | L5: =SUM(I5:K5) -> 36922 | M5: =L5-H5 -> 6326 | N5: paga | O5: 46154 | P5: =$E$1-G5 -> 319 | Q5: SWiFTs 03Feb26 ($15K)+18Mar ($7.978,50)+24/03 ($ 6.978,5)+12May ($6695) cobre saldos 187.25/Final + parcial 215.
A6: 187.25 Final | B6: POLYMAX EL GALO | C6: 7523 | D6: 45962 | E6: 45987 | F6: 60 days | G6: 46047 | H6: 1773.88 | K6: =M5 -> 6326 | L6: =SUM(I6:K6) -> 6326 | M6: =L6-H6 -> 4552.12 | N6: paga | O6: 46154 | P6: =$E$1-G6 -> 249 | Q6: SWIFT 12/05 $6695- arriba utilizado para cobrir saldo
A7: 215.25 | B7: POLYMAX EL GALO | C7: 8811 | D7: 45964 | E7: 46007 | F7: 60 days | G7: 46067 | H7: 13678.46 | K7: =3633.73+10044+0.73 -> 13678.46 | L7: =SUM(I7:K7) -> 13678.46 | M7: =L7-H7 -> 0 | N7: paga | O7: 46293 | P7: =$E$1-G7 -> 229 | Q7: Saldo SWIFT 12/05 arriba abona parcialmente esta invoice|SWIFT 15jun (10.044,00) cierra cuenta/ saldado 0,73 del swift de 28/09
A8: 017.26 & 021.26 | B8: POLYMAX EL GALO | C8: 9747 | D8: 46094 | E8: 46148 | F8: 60 days | G8: 46208 | H8: 21850.5 | K8: =6000+8000+8000-0.73 -> 21999.27 | L8: =SUM(I8:K8) -> 21999.27 | M8: =L8-H8 -> 148.77 | N8: paga | O8: 46293 | P8: =$E$1-G8 -> 88 | Q8: consolida con 021.26 / considerar $108 como juros/taxa - saldar | SWIFT 17/07 $6000+ SWIFT 10Sep $8.000+SWIFT 28/09 $8.000
A9: 053.26 | B9: POLYMAX EL GALO | C9: 11186 | D9: 46260 | E9: 46300 | G9: 46360 | H9: 19243 | I9: 148.77 | L9: =SUM(I9:K9) -> 148.77 | M9: =L9-H9 -> -19094.23 | N9: Futura | O9: 46360 | P9: =$E$1-G9 -> -64 | Q9: pedido nuevo en curso
E14: PGO | F14: Pendente | G14: Saldo | H14: Invoice ref.
A15: Nuevo pago parcial 12/05/2026 | D15: $6965 | E15: 6965 | F15: 1557.39 | G15: =E15-F15 -> 5407.61 | H15: 187.25
F16: 1773.88 | G16: =G15-F16 -> 3633.73 | H16: 187.25 final
E17: =E15-F15-F16 -> 3633.73 | F17: 13678.46 | G17: =F17-E17 -> 10044.73 | H17: 215.25
A18: Nuevo pago 15/06/2026 | D18: $10044 | E18: 10044 | G18: 0.73 | H18: 215.25
A25: pagos em mi ausencia
A26: 46275 | B26: 8000

Sheet Banking Data Conexao

Sheet SUNLOCK-flujo de credito 180526
A1: GESTIÓN DE CRÉDITO Y PAGOS - 2025 / 2026 | D1: =TODAY() -> 46296
S3: =SUM(I6:I8) -> 34416.09
A4: PROFORMA-INVOICE (EXPORT.) | B4: CLIENTE | C4: N° ORDEN | D4: FECHA PROFORM | E4: FECHA COLECTA | F4: TERMINO PAGO | G4: days | H4: FECHA VENCIMENTO/ DEADLINE | I4: TOTAL A PAGAR SEGÚN INVOICE US$ | J4: ANTICIPO (US$) | K4: NOTA CREDITO US$ | L4: PAGO FINAL US$ | M4: TOTAL SALDO DEBIDO HOY (US$) | N4: STATUS PAGO | O4: FECHA DE PAGO | P4: DIAS ATRASO | Q4: OBSERV. | S4: pagos 1er ac. | T4: pagos 2do ac
A5: 174.25 | B5: SUNLOCK SPA | C5: 6940 | D5: 45772 | E5: 45817 | F5: 30 days | G5: 30 | H5: 45847 | I5: 13839.68 | L5: 13839.68 | M5: =SUM(J5:L5)-I5 -> 0 | N5: paga | O5: 45947 | P5: =O5-H5 -> 100 | Q5: SWIFT 17Oct POR $13.839,68 | S5: 14591.42 | T5: 6575.25
A6: 180.25 | B6: SUNLOCK SPA | C6: 7173 | D6: 45805 | E6: 45855 | F6: 30 days | G6: 30 | H6: 45885 | I6: 4734.94 | K6: 3385.14 | L6: =Tabla7[[#This Row],[TOTAL A PAGAR SEGÚN INVOICE US$]]-K6 -> 1349.8 | M6: =SUM(J6:L6)-I6 -> 0 | N6: paga | O6: 46076 | P6: =O6-H6 -> 191 | Q6: SWIFT 23/02 por $14.591,42 - menos NC 3385,14 | S6: 5597.15
A7: 209.25 + 210.25 | B7: SUNLOCK SPA | C7: 8569/8798/8609 | D7: 45937 | E7: 45968 | F7: 30 days | G7: 30 | H7: 45998 | I7: 13908.91 | J7: 13908.91 | L7: =14591.42-1349.8+667.29 -> 13908.91 | M7: =J7-I7 -> 0 | N7: paga | O7: 46136 | P7: =O7-H7 -> 138 | Q7: Saldo de SWIFT 23/02 ($14.591,42) cubre parcialmente + SWIFT 24/04 $5597,15 cierra cuenta | S7: 5597.15
A8: 220.25 © | B8: SUNLOCK SPA | C8: 9030 /9035 | D8: 45985 | E8: 46010 | F8: 30 days | G8: 30 | H8: 46040 | I8: 15772.24 | J8: =4991.86 -> 4991.86 | L8: 5597.15 | M8: =SUM(J8:L8)-I8 -> -5183.23 | N8: parcial | O8: =TODAY() -> 46296 | P8: =O8-H8 -> 256 | Q8: Incluye flete|Swift 24/04 - credito parcial| SWIFT 01/06 (5597,15) abono parcial
A9: 003.26+ 005.26 + 007.26 | B9: SUNLOCK SPA | C9: 9157/9177/9207 | D9: 46010 | E9: 46073 | F9: 30 days | G9: 30 | H9: 46103 | I9: 18182.65 | M9: -18182.65 | N9: pendiente | O9: =TODAY() -> 46296 | P9: =O9-H9 -> 193 | Q9: marzo'26 | S9: =SUM(S5:S8) -> 25785.72 | T9: =SUM(T5:T8) -> 6575.25
A10: 011.26 | B10: SUNLOCK SPA | C10: 9522 | D10: 46077 | E10: 46140 | F10: 30 days | G10: 30 | H10: 46230 | I10: 24162.66 | J10: 6575.25 | M10: -17587.41 | N10: parcial | O10: 46230 | P10: =O10-H10 -> 0 | Q10: julho'26 - final| Incluye frete | SWIFT 04/05 $6.575,25 | S10: =S3-S9 -> 8630.37
I13: =SUM(I6:I8) -> 34416.09 | J13: urgent | K13: acuerdo de pago em 6X
I14: =I9 -> 18182.65 | J14: marzo | K14: pendiente?
I15: =I10 -> 24162.66 | J15: julio | K15: acuerdo pago de 33%-33%-33%
A19: 1) Acuerdo de pagar en 6 cuotas de USD 5.777,03 (19/03 - 06/04)
A20: =6*5777.03 -> 34662.18
A21: Esquema de pagos: | I21: Observ.
A22: 46136 | B22: 5659.15 | C22: =B22-5777.03 -> -117.88 | D22: =B22/5777.03 -> 0.97959505 | E22: ok 209/210- parcial 220.25 | I22: =5659.15-667.29 -> 4991.86 | J22: error em deuda total según carta de pagos recibida 27/04
A26: 2)Última Invoice 011.26 - Condiciones de pago especiales(29/04/26)
A27: 33% anticipado 33% 30d 33% 60
A28: =I10*33% -> 7973.6778 | B28: OK - 1ER ABONO | D28: =6575.25/I10 -> 0.27212443
A31: 1) *Invoices antiguas 180.25/209.25/210.25 /220.25 (deuda de $34.416,09) - Acuerdo de pagar en 6 cuotas de USD | I31: =34416.09/6 -> 5736.015 | J31: (19/03/2026)
A33: Esquema de pagos: | B33: Pago | C33: Dif | D33: Index | E33: Invoice(s) | H33: Observ. | I33: Balance
A34: 46136 | B34: 5597.15 | C34: =B34-$I$31 -> -138.865 | D34: =B34/$I$31 -> 0.97579068 | E34: 180/209/210 + parcial 220.25 | H34: Dif.de pago vs cuota | I34: =I13-B34 -> 28818.94
A35: 46174 | B35: =5597.15 -> 5597.15 | C35: =B35-$I$31 -> -138.865 | D35: =B35/$I$31 -> 0.97579068 | E35: 180/209/210 + parcial 220.25 | H35: sender charge 62+30 | I35: =I34-B35 -> 23221.79
A41: 2)**Última Invoice 011.26 | B41: =I10 -> 24162.66 | C41: - Condiciones de pago especiales(29/4/26) > | F41: 33% anticipado /33% 30d /33% 60 | J41: 8793.7 | K41: =B41*33% -> 7973.6778
A43: Esquema de pagos: | B43: Pago | C43: Dif. | D43: Index | E43: Invoice | H43: Observ. | I43: Balance
A44: 46146 | B44: 6575.25 | D44: =B44/24162.66 -> 0.27212443 | E44: 011.26 | H44: 1er Abono | I44: =I10-B44 -> 17587.41
D49: =5841.47*4 -> 23365.88
D55: =6575.25+8793.7+8793.7 -> 24162.65

Sheet Hoja1
A5: PROFORMA-INVOICE (EXPORT.) | B5: CLIENTE | C5: FECHA COLECTA | D5: TERMINO PAGO | E5: FECHA VENCIMENTO/ DEADLINE | F5: TOTAL A PAGAR SEGÚN INVOICE US$ | G5: ANTICIPO (US$) | H5: NOTA CREDITO US$ | I5: PAGO FINAL US$ | J5: TOTAL SALDO DEBIDO HOY (US$) | K5: STATUS PAGO | L5: FECHA DE PAGO | M5: DIAS ATRASO | N5: OBSERV.
A6: 209.25 + 210.25 | B6: SUNLOCK SPA | C6: 45968 | D6: 30 days | E6: 45998 | F6: 13908.91 | G6: 13241.62 | I6: 13241.62 | J6: -667.29 | K6: parcial | L6: 46076 | M6: 101 | N6: SWIFT 23/02 cubre parcialmente
A7: 220.25 | B7: SUNLOCK SPA | C7: 46010 | D7: 30 days | E7: 46040 | F7: 15772.24 | J7: -15772.24 | K7: pendiente | L7: 46099 | M7: 59 | N7: Incluye flete
A8: 003.26+ 005.26 + 007.26 | B8: SUNLOCK SPA | C8: 46073 | D8: 30 days | E8: 46103 | F8: 18182.65 | J8: -18182.65 | K8: pendiente | L8: 46099 | N8: marzo'26
A9: 011.26 | B9: SUNLOCK SPA | C9: 46112 | D9: 30 days | E9: 46142 | F9: 19925 | J9: -19925 | K9: futura | L9: 46099 | N9: abril'26

Sheet FLEX  CHILE
A1: Detalles de Suma de TOTAL DUE BALANCE (US$) - CLIENTE: FLEX CHILE, RECIB. PGTO: futura
A3: INVOICE (EXPORT.) | B3: CLIENTE | C3: PEDIDO TOTVS | D3: DATA INVOICE | E3: DATA COLETA | F3: PAYMENT TERMS | G3: days | H3: DATA VENCIMENTO/ DEADLINE | I3: TOTAL DUE PAYMENT-AS PER INVOICE US$ | J3: ADVANCE PAYMENT (US$) | K3: TOTAL DUE BALANCE (US$) | L3: VALOR TOTAL R$ | M3: NÚMERO NF | N3: RECIB. PGTO | O3: OBSERV.
A4: 183.25 | B4: FLEX CHILE | C4: (7178 / 7234) | D4: 45810 | E4: 45838 | F4: 90 Days | G4: 90 | H4: 45928 | I4: 11960 | J4: 11960 | K4: 0 | L4: 41676.25 | M4: 58965 | N4: futura | O4: (11.960,00) - Devolução cliente processada 23/07 -NF 059.324 - R$ 41.676,25
A5: 181.25 | B5: FLEX CHILE | C5: 7178/6880/7015 | D5: 45806 | E5: 45837 | F5: 90 Days | G5: 90 | H5: 45927 | I5: 7360 | J5: 7360 | K5: 0 | L5: - | M5: 58965 | N5: futura | O5: faturado / 6880 / 7015 -- Invoice saida 167.25+168.25+181.25 (12.665,19) - 7.360,00
A6: 163.25 | B6: FLEX CHILE | C6: 6752 / 6868 / 6949 | D6: 45754 | E6: 45792 | F6: 90 Days | G6: 90 | H6: 45882 | K6: 0 | L6: - | M6: 58048/57.898 | N6: futura | O6: 6752 / 6868 / 6949; ajustada para 164.25. Ver valores nessa cell
A7: 176.25 | B7: FLEX CHILE | C7: 6949 | D7: 45776 | E7: 45792 | F7: 90 Days | G7: 90 | H7: 45882 | I7: 1840 | K7: 1840 | L7: - | N7: futura | O7: parcialmente atendido
A8: 166.25 | B8: FLEX CHILE | C8: 6875 | D8: 45754 | E8: 45771 | F8: 90 Days | G8: 90 | H8: 45861 | I8: 2222.72 | K8: 2222.72 | L8: 12642.83 | M8: 57775 | N8: futura | O8: will Charge--Rep. Qualidade. 2.222,72
A9: 168.25 | B9: FLEX CHILE | C9: 6880 / 7015 | D9: 45784 | E9: 45814 | F9: 90 Days | G9: 90 | H9: 45904 | I9: 3375 | K9: 3375 | L9: - | M9: - | N9: futura | O9: 167+168+181 - inv 167.25 + 168.25 juntas para faturamento - Fup
A10: 189.25 | B10: FLEX CHILE | C10: 7630 | D10: 45848 | E10: 45879 | F10: 90 Days | G10: 90 | H10: 45969 | I10: 4123 | K10: 4123 | N10: futura
A11: 167.25 | B11: FLEX CHILE | C11: 6880/ 7178 | D11: 45769 | E11: 45807 | F11: 90 Days | G11: 90 | H11: 45897 | I11: 12665.19 | K11: 12665.19 | L11: 71657.84 | M11: 58433/58.358 | N11: futura | O11: 167+168+181/ add +400/+200 dos mesmos artigos 19/5 (125.25 amostras)
A12: 164.25 | B12: FLEX CHILE | C12: 6752 / 6868 / 6949/6816 /6623 | D12: 45777 | E12: 45792 | F12: 90 Days | G12: 90 | H12: 45882 | I12: 63969.62 | K12: 63969.62 | L12: 414202.66 | M12: 58048/57.898/57.985/57.984 | N12: futura | O12: PV 6752 / 6868 / 6949

Sheet DIVINO
A1: Detalles de Suma de TOTAL DUE BALANCE (US$) - CLIENTE: DIVINO, RECIB. PGTO: futura
A3: INVOICE (EXPORT.) | B3: CLIENTE | C3: PEDIDO TOTVS | D3: DATA INVOICE | E3: DATA COLETA | F3: PAYMENT TERMS | G3: days | H3: DATA VENCIMENTO/ DEADLINE | I3: TOTAL DUE PAYMENT-AS PER INVOICE US$ | J3: ADVANCE PAYMENT (US$) | K3: TOTAL DUE BALANCE (US$) | L3: VALOR TOTAL R$ | M3: NÚMERO NF | N3: RECIB. PGTO | O3: OBSERV.
A4: 184.25 | B4: DIVINO | C4: 7235 (7068 / 7235) | D4: 45810 | E4: 45840 | F4: 50% Pre Payment - 50% After Received | G4: 30 | H4: 45870 | I4: 30148.81 | K4: 30148.81 | L4: 165091.87 | M4: 58963 | N4: futura | O4: despacho junto c/173.25 e 177.25/ Invoice revisada 02Jul -(esta Inv.- 30.148,81)
A5: 188.25 | B5: DIVINO | C5: 7503 | D5: 45840 | E5: 45871 | F5: 50% Pre Payment - 50% After Received | G5: 30 | H5: 45901 | I5: 58465 | K5: 58465 | N5: futura | O5: Alteraçã valor proforma por alteração código artigo
A8: NUEVO SWIFT
A9: 17563.81 | B9: 45848 | C9: Cual Invoice????

Sheet template de comunicação
A1: Señores __________
A3: Buenos días Estimados ______,
A5: Informo que el (los) siguiente(s) pedido(s) ya ha(n) sido despachados y quedamos atentos a la confirmación del (los) respectivo(s) pago(s) con copia del documento SWIFT:
A7: INVOICE | B7: TOTAL VALUE $ | C7: ADVANCE PAYMENT | D7: TOTAL DUE BALANCE
A10: Anexo documento con la información sobre los detalles bancarios y copia de la factura.
A12: Mil Gracias de antemano por su atención. Quedamos a su disposición.
A14: Cordiales Saludos,

Sheet contatos chaves
A1: CONEXÃO MALHAS - CONTATOS CHAVES / CLIENTES ATIVOS
A3: Regiao | B3: Sub-regiao | C3: Clientes | D3: Ativos | E3: Inativos | F3: Prospect | G3: Potencial | H3: Estrategicos | I3: Sensiveis | J3: contato | K3: cargo | L3: email | M3: telefone | N3: Observ.
A4: Chile | B4: Santiago | C4: Flex Equipos de Descanso | D4: Sim | E4: - | F4: - | G4: Grande | H4: Sim | I4: Sim | J4: Paulina Mena | K4: Compras | L4: paulina.mena@flex.es | M4: 56 96205 0626 | N4: amostras/ desenvolvimento/OC
A5: Chile | B5: Santiago | C5: Flex Equipos de Descanso | D5: Sim | G5: Grande | H5: Sim | I5: Sim | J5: Danae Briones | K5: Importações | L5: danae.briones@flex.es | M5: +56 9 5514 2584
A6: Chile | B6: Santiago | C6: Flex Equipos de Descanso | D6: Sim | G6: Grande | H6: Sim | I6: Sim | J6: Francesca Seitz | K6: Marketing | L6: francesca.seitz@flex.es | M6: +56 9 3451 9331
A7: Chile | B7: Santiago | C7: Flex Equipos de Descanso | D7: Sim | G7: Grande | H7: Sim | I7: Sim | J7: Angelo Almonacid | K7: Supply | L7: angelo.almonacid@flex.es | M7: +56 9 4400 6214 | N7: Manager of others
